Weights & Biases tracking enabled.
FP16 Run: False
Dynamic Loss Scaling: True
Distributed Run: False
cuDNN Enabled: True
cuDNN Benchmark: False
An error occurred during training: train() got an unexpected keyword argument 'use_wandb'
Traceback (most recent call last):
  File "<ipython-input-11-f19ded8726e7>", line 37, in <module>
    use_wandb=use_wandb
TypeError: train() got an unexpected keyword argument 'use_wandb'